<?xml version="1.0"?>
<robot xmlns:xacro="http://www.ros.org/wiki/xacro" name="dodo_model">

 
 
  <!-- Root link -->
  <link name="base_link">
    
  </link>

  
 
  <!-- Back caster -->
  <joint name="back_caster_link_joint" type="continuous">
    <parent link="base_link"/>
    <child link="back_caster_link"/>
    <origin rpy="0 0 0" xyz="-0.19276 0 0.0"/>
    <axis xyz="0 0 0"/>
  </joint>

  <link name="back_caster_link">
    <inertial>
    <origin rpy="0 0 0" xyz="0 0 -0.39"/>
      <mass value="1.0"/>
      <inertia ixx="0.00108" ixy="0" ixz="0" iyy="0.00108" iyz="0" izz="0.00108"/>
    </inertial>
    <collision>
    <origin rpy="0 0 0" xyz="0 0 -0.4"/>
      <geometry>
        <sphere radius="0.03"/>
      </geometry>
    </collision>
    <visual>
    <origin rpy="0 0 0" xyz="0 0 -0.4"/>
      <geometry>
        <sphere radius="0.03"/>
      </geometry>
    </visual>
  </link>

  <!-- Front caster -->
  <joint name="front_caster_link_joint" type="continuous">
    <parent link="base_link"/>
    <child link="front_caster_link"/>
    <origin rpy="0 0 0" xyz="0.19276 0 0.001"/>
    <axis xyz="0 0 1"/>
  </joint>

  <link name="front_caster_link">
    <inertial>
    <origin rpy="0 0 0" xyz="0 0 -0.39"/>
      <mass value="1.0"/>
      <inertia ixx="0.00108" ixy="0" ixz="0" iyy="0.00108" iyz="0" izz="0.00108"/>
    </inertial>
    <collision>
    <origin rpy="0 0 0" xyz="0 0 -0.4"/>
      <geometry>
        <sphere radius="0.03"/>
      </geometry>
    </collision>
    <visual>
    <origin rpy="0 0 0" xyz="0 0 -0.4"/>
      <geometry>
        <sphere radius="0.03"/>
      </geometry>
    </visual>
  </link>

  <!-- Left wheel -->
  <joint name="left_wheel_link_joint" type="continuous">
    <parent link="base_link"/>
    <child link="left_wheel_link"/>
    <origin rpy="1.6 0 0" xyz="0 0.19 0.001"/>
    <axis xyz="0 0 1"/>
  </joint>

  <link name="left_wheel_link">
    <inertial>
    <origin rpy="0 0 0" xyz="0 -0.39 0"/>
      <mass value="2.0"/>
      <inertia ixx="0.00583" ixy="0" ixz="0" iyy="0.00583" iyz="0" izz="0.0025"/>
    </inertial>
    <collision>
    <origin rpy="0 0 0" xyz="0 -0.4 0"/>
      <geometry>
        <cylinder radius="0.04" length="0.02"/>
      </geometry>
    </collision>
    <visual>
    <origin rpy="0 0 0" xyz="0 -0.4 0"/>
      <geometry>
        <cylinder radius="0.04" length="0.02"/>
      </geometry>
    </visual>
  </link>

  <!-- Right wheel -->
  <joint name="right_wheel_link_joint" type="continuous">
    <parent link="base_link"/>
    <child link="right_wheel_link"/>
    <origin rpy="1.6 0 0" xyz="0 -0.19 0.001
    "/>
    <axis xyz="0 0 1"/>
  </joint>

  <link name="right_wheel_link">
    <inertial>
    <origin rpy="0 0 0" xyz="0 -0.39 0"/>
      <mass value="2.0"/>
      <inertia ixx="0.00583" ixy="0" ixz="0" iyy="0.00583" iyz="0" izz="0.0025"/>
    </inertial>
    <collision>
    <origin rpy="0 0 0" xyz="0 -0.4 0"/>
      <geometry>
        <cylinder radius="0.04" length="0.02"/>
      </geometry>
    </collision>
    <visual>
      <origin rpy="0 0 0" xyz="0 -0.4 0"/>
      <geometry>
        <cylinder radius="0.04" length="0.02"/>
      </geometry>
    </visual>
  </link>

  <!-- Body link -->
  <joint name="body_joint" type="fixed">
    <parent link="base_link"/>
    <child link="body_link"/>
    <origin rpy="0 0 0" xyz="0 0 0.0"/>
  </joint>

  <link name="body_link">
    <inertial>
    <origin rpy="0 0 0" xyz="0 0 0.2"/>
      <mass value="15.0"/>
      <inertia ixx="2.079" ixy="0" ixz="0" iyy="2.079" iyz="0" izz="0.5609"/>
    </inertial>
    <collision>
      <origin rpy="0 0 0" xyz="0 0 0.05"/>
      <geometry>
        <cylinder radius="0.27358" length="0.89942"/>
      </geometry>
    </collision>
    <visual>
    <origin rpy="0 0 0" xyz="0 0 -0.4"/>
      <geometry>
        <mesh filename="package://dodo_description/meshes/Cylinder.stl" scale="0.26 0.26 0.12844"/>
      </geometry>
    </visual>
  </link>

  <!-- Materials -->
  <material name="Material.001">
    <color rgba="0.8 0.8 0.8 1"/>
  </material>

</robot>
